Workbook

Sheet 連絡網_201801
G3: 日浦 健二 | K3: 福岡 法和 | N3: 松田 豪之扶 | Q3: 出口 栄一 | T3: 野田 哲男 | W3: 森 美弥
G4: =IF(G3="","",VLOOKUP(G3,表示電話番号一覧!$C:$F,4,FALSE)) -> 080-3754-3568 | K4: =IF(K3="","",VLOOKUP(K3,表示電話番号一覧!$C:$F,4,FALSE)) -> 080-4862-3745 | N4: =IF(N3="","",VLOOKUP(N3,表示電話番号一覧!$C:$F,4,FALSE)) -> 090-1791-5298 | Q4: =IF(Q3="","",VLOOKUP(Q3,表示電話番号一覧!$C:$F,4,FALSE)) -> 090-3104-3067 | T4: =IF(T3="","",VLOOKUP(T3,表示電話番号一覧!$C:$F,4,FALSE)) -> 080-3384-9464 | W4: =IF(W3="","",VLOOKUP(W3,表示電話番号一覧!$C:$F,4,FALSE)) -> 080-4584-2248
G5: hiura@mmin-net.co.jp
K6: 三浦 学 | N6: 川上 悟 | Q6: 水澤 浩二郎 | T6: 松岡 幸恵 | W6: 高橋 寿実 | Z6: 小宮 慶宏 | AC6: 小宮 静佳
K7: =IF(K6="","",VLOOKUP(K6,表示電話番号一覧!$C:$F,4,FALSE)) -> 070-3514-2223 | N7: =IF(N6="","",VLOOKUP(N6,表示電話番号一覧!$C:$F,4,FALSE)) -> 070-3541-0264 | Q7: =IF(Q6="","",VLOOKUP(Q6,表示電話番号一覧!$C:$F,4,FALSE)) -> 080-7933-6122 | T7: 090-2442-2655 | W7: =IF(W6="","",VLOOKUP(W6,表示電話番号一覧!$C:$F,4,FALSE)) -> 090-9811-6923 | Z7: 070-3831-8111 | AC7: 080-5746-0499
K9: 松本 泰貴 | N9: 飯嶋 由佳李 | Q9: 高石 薫 | T9: 安部 亮 | W9: 下地 浩子 | Z9: 重白 一久
K10: =IF(K9="","",VLOOKUP(K9,表示電話番号一覧!$C:$F,4,FALSE)) -> 080-4581-1554 | N10: =IF(N9="","",VLOOKUP(N9,表示電話番号一覧!$C:$F,4,FALSE)) -> 080-3431-6721 | Q10: =IF(Q9="","",VLOOKUP(Q9,表示電話番号一覧!$C:$F,4,FALSE)) -> 080-3566-8973 | T10: =IF(T9="","",VLOOKUP(T9,表示電話番号一覧!$C:$F,4,FALSE)) -> 070-3854-6729 | W10: =IF(W9="","",VLOOKUP(W9,表示電話番号一覧!$C:$F,4,FALSE)) -> 080-9870-0199 | Z10: =IF(Z9="","",VLOOKUP(Z9,表示電話番号一覧!$C:$F,4,FALSE)) -> 070-3852-1849
B12: 社長不在の場合は | K12: 伊藤 恵 | N12: 佐々木 恵美 | Q12: 工藤 純子 | T12: 岸 優里
B13: 経営管理部長が | K13: =IF(K12="","",VLOOKUP(K12,表示電話番号一覧!$C:$F,4,FALSE)) -> 080-3270-6875 | N13: =IF(N12="","",VLOOKUP(N12,表示電話番号一覧!$C:$F,4,FALSE)) -> 090-9808-6751 | Q13: =IF(Q12="","",VLOOKUP(Q12,表示電話番号一覧!$C:$F,4,FALSE)) -> 080-9802-4443 | T13: =IF(T12="","",VLOOKUP(T12,表示電話番号一覧!$C:$F,4,FALSE)) -> 080-3606-3448
B14: 代行して連絡をする
N15: 斯波 聡 | Q15: 野口 直樹 | T15: 日吉 健一郎 | W15: 松山 大輔
K16: =IF(K15="","",VLOOKUP(K15,表示電話番号一覧!$C:$F,4,FALSE)) | N16: =IF(N15="","",VLOOKUP(N15,表示電話番号一覧!$C:$F,4,FALSE)) -> 080-4373-7684 | Q16: =IF(Q15="","",VLOOKUP(Q15,表示電話番号一覧!$C:$F,4,FALSE)) -> 070-3854-6728 | T16: =IF(T15="","",VLOOKUP(T15,表示電話番号一覧!$C:$F,4,FALSE)) -> 070-3854-6730 | W16: =IF(W15="","",VLOOKUP(W15,表示電話番号一覧!$C:$F,4,FALSE)) -> 070-3864-2675
B18: 橋本 修一 | G18: 白井 正美 | K18: 宮﨑 正行 | N18: 清水 豊 | Q18: 明石 健太 | T18: 齊藤 翔 | W18: 鑪 康介 | Z18: 鈴木 貴一
B19: =IF(B18="","",VLOOKUP(B18,表示電話番号一覧!$C:$F,4,FALSE)) -> 090-9025-2358 | G19: =IF(G18="","",VLOOKUP(G18,表示電話番号一覧!$C:$F,4,FALSE)) -> 080-3566-8951 | K19: =IF(K18="","",VLOOKUP(K18,表示電話番号一覧!$C:$F,4,FALSE)) -> 080-3451-6474 | N19: =IF(N18="","",VLOOKUP(N18,表示電話番号一覧!$C:$F,4,FALSE)) -> 080-4373-7695 | Q19: =IF(Q18="","",VLOOKUP(Q18,表示電話番号一覧!$C:$F,4,FALSE)) -> 080-3566-8966 | T19: =IF(T18="","",VLOOKUP(T18,表示電話番号一覧!$C:$F,4,FALSE)) -> 070-3629-7215 | W19: =IF(W18="","",VLOOKUP(W18,表示電話番号一覧!$C:$F,4,FALSE)) -> 070-3661-7937 | Z19: =IF(Z18="","",VLOOKUP(Z18,表示電話番号一覧!$C:$F,4,FALSE)) -> 070-4579-7534
B20: mmi_0001@me.com | G20: shirai-mmi@ezweb.ne.jp
N21: 中山 透 | Q21: 加藤 純一 | T21: 瀧上 和樹 | W21: 鈴木 武史 | Z21: 松本 大輔
N22: =IF(N21="","",VLOOKUP(N21,表示電話番号一覧!$C:$F,4,FALSE)) -> 080-4581-1553 | Q22: =IF(Q21="","",VLOOKUP(Q21,表示電話番号一覧!$C:$F,4,FALSE)) -> 080-3566-8974 | T22: =IF(T21="","",VLOOKUP(T21,表示電話番号一覧!$C:$F,4,FALSE)) -> 080-4373-7793 | W22: =IF(W21="","",VLOOKUP(W21,表示電話番号一覧!$C:$F,4,FALSE)) -> 070-3541-0263 | Z22: =IF(Z21="","",VLOOKUP(Z21,表示電話番号一覧!$C:$F,4,FALSE)) -> 070-3843-4639
N24: 鈴木 圭 | Q24: 伊藤 祐介 | T24: 渡邊 良子 | W24: 大木 望愛 | Z24: 二村 眞弓 | AC24: 矢吹 智代
N25: =IF(N24="","",VLOOKUP(N24,表示電話番号一覧!$C:$F,4,FALSE)) -> 070-2165-7714 | Q25: =IF(Q24="","",VLOOKUP(Q24,表示電話番号一覧!$C:$F,4,FALSE)) -> 080-3566-8978 | T25: =IF(T24="","",VLOOKUP(T24,表示電話番号一覧!$C:$F,4,FALSE)) -> 070-4201-6852 | W25: =IF(W24="","",VLOOKUP(W24,表示電話番号一覧!$C:$F,4,FALSE)) -> 090-2402-7362 | Z25: =IF(Z24="","",VLOOKUP(Z24,表示電話番号一覧!$C:$F,4,FALSE)) -> 090-6950-1788 | AC25: =IF(AC24="","",VLOOKUP(AC24,表示電話番号一覧!$C:$F,4,FALSE)) -> 090-1047-0938
K27: 白鳥 大介 | N27: 伏見 晃一 | Q27: 東郷 一哉
K28: =IF(K27="","",VLOOKUP(K27,表示電話番号一覧!$C:$F,4,FALSE)) -> 090-6033-7021 | N28: =IF(N27="","",VLOOKUP(N27,表示電話番号一覧!$C:$F,4,FALSE)) -> 080-3566-8958 | Q28: =IF(Q27="","",VLOOKUP(Q27,表示電話番号一覧!$C:$F,4,FALSE)) -> 080-3446-7228 | Z28: =IF(Z27="","",VLOOKUP(Z27,表示電話番号一覧!$C:$F,4,FALSE))
Q30: 長﨑 義徳 | T30: 関 英夫 | W30: 佐藤 友岐夫 | Z30: 下田 隆弘
Q31: =IF(Q30="","",VLOOKUP(Q30,表示電話番号一覧!$C:$F,4,FALSE)) -> 070-3601-5755 | T31: =IF(T30="","",VLOOKUP(T30,表示電話番号一覧!$C:$F,4,FALSE)) -> 070-3609-3812 | W31: =IF(W30="","",VLOOKUP(W30,表示電話番号一覧!$C:$F,4,FALSE)) -> 080-3566-8955 | Z31: =IF(Z30="","",VLOOKUP(Z30,表示電話番号一覧!$C:$F,4,FALSE)) -> 080-4106-8296
K32: Ism館長
K33: 瀧田 賢吾 | Q33: 市川 孝 | T33: 川崎 哲也
K34: =IF(K33="","",VLOOKUP(K33,表示電話番号一覧!$C:$F,4,FALSE)) -> 080-3566-8957 | Q34: =IF(Q33="","",VLOOKUP(Q33,表示電話番号一覧!$C:$F,4,FALSE)) -> 070-3533-7393 | T34: 070-4504-5778
K36: 磯 孝宏 | N36: 浅川 喜希 | Q36: 朝長 比奈子
K37: =IF(K36="","",VLOOKUP(K36,表示電話番号一覧!$C:$F,4,FALSE)) -> 080-9819-8256 | N37: =IF(N36="","",VLOOKUP(N36,表示電話番号一覧!$C:$F,4,FALSE)) -> 080-5190-8426 | Q37: =IF(Q36="","",VLOOKUP(Q36,表示電話番号一覧!$C:$F,4,FALSE)) -> 080-4083-8534 | W37: =IF(W36="","",VLOOKUP(W36,表示電話番号一覧!$C:$F,4,FALSE))
G39: 羽場 康雄 | K39: 曽我 尚子 | N39: 新間 豊 | Q39: 高橋 和夫 | T39: 松本 千絵 | W39: 梅津 香織 | Z39: 岡田 仁美
G40: =IF(G39="","",VLOOKUP(G39,表示電話番号一覧!$C:$F,4,FALSE)) -> 080-4905-6111 | K40: =IF(K39="","",VLOOKUP(K39,表示電話番号一覧!$C:$F,4,FALSE)) -> 090-4241-0567 | N40: =IF(N39="","",VLOOKUP(N39,表示電話番号一覧!$C:$F,4,FALSE)) -> 090-4855-2641 | Q40: =IF(Q39="","",VLOOKUP(Q39,表示電話番号一覧!$C:$F,4,FALSE)) -> 090-4938-1866 | T40: =IF(T39="","",VLOOKUP(T39,表示電話番号一覧!$C:$F,4,FALSE)) -> 080-2053-5731 | W40: =IF(W39="","",VLOOKUP(W39,表示電話番号一覧!$C:$F,4,FALSE)) -> 090-9855-5534 | Z40: =IF(Z39="","",VLOOKUP(Z39,表示電話番号一覧!$C:$F,4,FALSE)) -> 080-2333-4494
G41: haba@mmin-net.co.jp
K42: 青木 博之 | N42: 檜垣 壮 | Q42: 田中 宏樹 | T42: 大澤 邦明 | W42: 桑田 拓也
K43: 090-3238-0679 | N43: =IF(N42="","",VLOOKUP(N42,表示電話番号一覧!$C:$F,4,FALSE)) -> 080-3936-6183 | Q43: =IF(Q42="","",VLOOKUP(Q42,表示電話番号一覧!$C:$F,4,FALSE)) -> 080-3566-8975 | T43: =IF(T42="","",VLOOKUP(T42,表示電話番号一覧!$C:$F,4,FALSE)) -> 080-4373-8694 | W43: 090-1213-2144
K45: 浅野 博 | N45: 金 英珉 | Q45: 安藤 美穂 | T45: 橋本 知明 | W45: 飯塚 武彦
K46: =IF(K45="","",VLOOKUP(K45,表示電話番号一覧!$C:$F,4,FALSE)) -> 080-3566-8956 | N46: =IF(N45="","",VLOOKUP(N45,表示電話番号一覧!$C:$F,4,FALSE)) -> 070-3547-4367 | Q46: =IF(Q45="","",VLOOKUP(Q45,表示電話番号一覧!$C:$F,4,FALSE)) -> 070-3533-7394 | T46: =IF(T45="","",VLOOKUP(T45,表示電話番号一覧!$C:$F,4,FALSE)) -> 080-9640-2656 | W46: =IF(W45="","",VLOOKUP(W45,表示電話番号一覧!$C:$F,4,FALSE)) -> 070-3852-1867
N48: 宋 晟赫 | Q48: 尹 美英 | T48: 金 恩志 | W48: 朴 秀彬 | Z48: ヴォン ティ リエウ
N49: =IF(N48="","",VLOOKUP(N48,表示電話番号一覧!$C:$F,4,FALSE)) -> 070-3868-5523 | Q49: =IF(Q48="","",VLOOKUP(Q48,表示電話番号一覧!$C:$F,4,FALSE)) -> 070-3836-5522 | T49: =IF(T48="","",VLOOKUP(T48,表示電話番号一覧!$C:$F,4,FALSE)) -> 070-3862-8149 | W49: =IF(W48="","",VLOOKUP(W48,表示電話番号一覧!$C:$F,4,FALSE)) -> 080-3566-8953 | Z49: =IF(Z48="","",VLOOKUP(Z48,表示電話番号一覧!$C:$F,4,FALSE)) -> 070-3872-7701
B51: マルハン危機情報センター | I51: ※ 震災等の安否確認では、連絡がとりにくい状況が予測されるため、キントーンのアプリ
B52: ０３－５２２０－４９８４ | I52: 『社員情報マスタ』の安否確認欄に 本人の怪我の有無、家族・家屋の状況』を記入してください
I53: キントーンに入力できない場合は、部門長にメールで報告してください

Sheet 拠点責任者
B1: 各拠点の責任者および連絡先
A2: 拠点 | B2: 住所 | C2: 電話 | D2: 責任者 | F2: 電話 | G2: メンバー
A3: 神田本社 | B3: 東京都千代田区神田錦町1-21-1 | C3: 03-3293-8686 | D3: 正 | E3: 羽場 康雄 | F3: =IF(E3="","",VLOOKUP(E3,表示電話番号一覧!$C:$F,4,FALSE)) -> 080-4905-6111 | G3: その他多数
D4: 副 | E4: 白井 正美 | F4: =IF(E4="","",VLOOKUP(E4,表示電話番号一覧!$C:$F,4,FALSE)) -> 080-3566-8951
A5: 首都圏 テクニカルセンター | B5: 埼玉県越谷市川柳町5-149-1 | C5: 048-988-8688 | D5: 正 | E5: 宮﨑 正行 | F5: =IF(E5="","",VLOOKUP(E5,表示電話番号一覧!$C:$F,4,FALSE)) -> 080-3451-6474 | G5: 清水 豊 | H5: 明石 健太 | I5: 齊藤 翔 | J5: 鑪（たたら）康介 | K5: 中山 透 | L5: 加藤 純一
D6: 副 | F6: =IF(E6="","",VLOOKUP(E6,表示電話番号一覧!$C:$F,4,FALSE)) | G6: 瀧上 和樹 | H6: 鈴木 武史 | I6: 松本 大輔
A7: 仙台営業所 | B7: 宮城県仙台市宮城野区田子上3-1-101 | C7: 022-207-8686 | D7: 正 | E7: 東郷 一哉 | F7: =IF(E7="","",VLOOKUP(E7,表示電話番号一覧!$C:$F,4,FALSE)) -> 080-3446-7228 | G7: 伊藤 恵 | H7: 佐々木 恵美 | I7: 工藤 純子 | J7: 岸 優里 | K7: 斯波 聡
D8: 副 | F8: =IF(E8="","",VLOOKUP(E8,表示電話番号一覧!$C:$F,4,FALSE))
A9: 静岡営業所 | B9: 静岡県静岡市駿河区富士見台1-4-85 メガシティ静岡 内 | C9: 054-204-6670 | D9: 正 | E9: 市川 孝 | F9: =IF(E9="","",VLOOKUP(E9,表示電話番号一覧!$C:$F,4,FALSE)) -> 070-3533-7393 | G9: 川崎 哲也
D10: 副 | F10: =IF(E10="","",VLOOKUP(E10,表示電話番号一覧!$C:$F,4,FALSE))
A11: 静岡東営業所 | B11: 静岡県富士宮市宮原２７６－３ １階 B号室 | C11: 0544-21-3630 | D11: 正 | E11: 野口 直樹 | F11: 070-3854-6728 | G11: 松山 大輔 | H11: 日吉 健一郎
D12: 副 | F12: =IF(E12="","",VLOOKUP(E12,表示電話番号一覧!$C:$F,4,FALSE))
A13: シェラトン | B13: 東京都港区白金台1丁目1-50 | C13: 070-3831-8032 | D13: 正 | E13: 金 英珉 | F13: =IF(E13="","",VLOOKUP(E13,表示電話番号一覧!$C:$F,4,FALSE)) -> 070-3547-4367 | G13: 安藤 美穂 | H13: ソン ソンショク | I13: ユン ミヨン | J13: 金 恩志 | K13: 朴 秀彬 | L13: 安藤 美穂
D14: 副 | F14: =IF(E14="","",VLOOKUP(E14,表示電話番号一覧!$C:$F,4,FALSE)) | G14: 橋本 知明 | H14: ヴォン ティ リエウ | I14: 飯塚 武彦
A15: Ism緑ヶ丘 | B15: 千葉県八千代市緑ヶ丘西2-13-3 | C15: 047-458-4446 （FAXも同番号） | D15: 正 | E15: 瀧田 賢吾 | F15: =IF(E15="","",VLOOKUP(E15,表示電話番号一覧!$C:$F,4,FALSE)) -> 080-3566-8957
D16: 副 | F16: =IF(E16="","",VLOOKUP(E16,表示電話番号一覧!$C:$F,4,FALSE))

Sheet 表示電話番号一覧
F1: （会社携帯を優先表示） | I1: ※個人の番号は、外部に伝えないこと。
B2: 社員番号 | C2: 氏名 | D2: 所属部署 | F2: 表示電話番号 | H2: 会社携帯 | I2: 個人携帯 | J2: 雇用形態
B3: 961273 | C3: 橋本 修一 | D3: 社長 | F3: =IF(H3="",I3,H3) -> 090-9025-2358 | H3: 090-9025-2358 | J3: 出向
B4: 3106002 | C4: 白井 正美 | D4: 総合建物管理事業部 | F4: =IF(H4="",I4,H4) -> 080-3566-8951 | H4: 080-3566-8951 | I4: 090-4715-6409
B5: 3110005 | C5: 白鳥 大介 | D5: 総合建物管理事業部 | F5: =IF(H5="",I5,H5) -> 090-6033-7021 | H5: 090-6033-7021 | I5: 090-4967-4045
B6: 3120018 | C6: 鈴木 圭 | D6: 事業管理チーム | F6: =IF(H6="",I6,H6) -> 070-2165-7714 | H6: 070-2165-7714 | I6: 080-6652-2455
B7: 3107001 | C7: 伊藤 祐介 | D7: 事業管理チーム | F7: =IF(H7="",I7,H7) -> 080-3566-8978 | H7: 080-3566-8978 | I7: 090-7821-0953
B8: 3120021 | C8: 渡邊 良子 | D8: 事業管理チーム | F8: =IF(H8="",I8,H8) -> 070-4201-6852 | I8: 070-4201-6852
B9: 3170001 | C9: 二村 眞弓 | D9: 事業管理チーム | F9: =IF(H9="",I9,H9) -> 090-6950-1788 | I9: 090-6950-1788 | J9: 時給
B10: 3170020 | C10: 浦澤 佳子 | D10: 事業管理チーム | F10: =IF(H10="",I10,H10) -> 080-3480-2214 | I10: 080-3480-2214 | J10: 時給
C11: 矢吹 智代 | D11: 事業管理チーム | F11: =IF(H11="",I11,H11) -> 090-1047-0938 | I11: 090-1047-0938 | J11: 派遣
B12: 3130014 | C12: 松本 泰貴 | D12: 環境管理チーム | F12: =IF(H12="",I12,H12) -> 080-4581-1554 | H12: 080-4581-1554 | I12: 050-3645-6034
B13: 3130013 | C13: 飯嶋 由佳李 | D13: 環境管理チーム | F13: =IF(H13="",I13,H13) -> 080-3431-6721 | H13: 080-3431-6721 | I13: 080-2342-1741
B14: 3150013 | C14: 高石 薫 | D14: 環境管理チーム | F14: =IF(H14="",I14,H14) -> 080-3566-8973 | H14: 080-3566-8973 | I14: 090-2181-3938
B15: 3160021 | C15: 安部 亮 | D15: 環境管理チーム | F15: =IF(H15="",I15,H15) -> 070-3854-6729 | H15: 070-3854-6729 | I15: 090-7692-9744
B16: 3150004 | C16: 下地 浩子 | D16: 環境管理チーム | F16: =IF(H16="",I16,H16) -> 080-9870-0199 | H16: 080-9870-0199 | I16: 090-6167-8239 | J16: 契約
B17: 3111005 | C17: 伊藤 恵 | D17: 環境管理サテライトチーム | F17: =IF(H17="",I17,H17) -> 080-3270-6875 | H17: 080-3270-6875 | I17: 090-8783-6103
B18: 3120016 | C18: 佐々木 恵美 | D18: 環境管理サテライトチーム | F18: =IF(H18="",I18,H18) -> 090-9808-6751 | H18: 090-9808-6751 | I18: 080-1807-0700
B19: 3120023 | C19: 斯波 聡 | D19: 環境管理サテライトチーム | F19: =IF(H19="",I19,H19) -> 080-4373-7684 | H19: 080-4373-7684 | I19: 090-5831-6419
B20: 3140003 | C20: 工藤 純子 | D20: 環境管理サテライトチーム | F20: =IF(H20="",I20,H20) -> 080-9802-4443 | H20: 080-9802-4443 | I20: 090-5359-4302
B21: 3160010 | C21: 岸 優里 | D21: 環境管理サテライトチーム | F21: =IF(H21="",I21,H21) -> 080-3606-3448 | H21: 080-3606-3448 | I21: 080-1840-0945
B22: 3160020 | C22: 野口 直樹 | D22: 環境管理サテライトチーム | F22: =IF(H22="",I22,H22) -> 070-3854-6728 | H22: 070-3854-6728 | I22: 090-6761-3293
B23: 3160022 | C23: 日吉 健一郎 | D23: 環境管理サテライトチーム | F23: =IF(H23="",I23,H23) -> 070-3854-6730 | H23: 070-3854-6730 | I23: 080-3633-2853
B24: 3160023 | C24: 松山 大輔 | D24: 環境管理サテライトチーム | F24: =IF(H24="",I24,H24) -> 070-3864-2675 | H24: 070-3864-2675 | I24: 090-3567-6127
B25: 1000058 | C25: 嶋村 健一 | D25: 環境管理サテライトチーム | F25: =IF(H25="",I25,H25) -> 070-4579-7535 | H25: 070-4579-7535 | J25: 出向
B26: 3109005 | C26: 伏見 晃一 | D26: 施設管理チーム | F26: =IF(H26="",I26,H26) -> 080-3566-8958 | H26: 080-3566-8958 | I26: 090-1462-7645
B27: 3107002 | C27: 瀧田 賢吾 | D27: 施設管理チーム | F27: =IF(H27="",I27,H27) -> 080-3566-8957 | H27: 080-3566-8957 | I27: 090-8034-4160
B28: 3120007 | C28: 下田 隆弘 | D28: 施設管理チーム | F28: =IF(H28="",I28,H28) -> 080-4106-8296 | H28: 080-4106-8296 | I28: 080-5867-5110
B29: 3150021 | C29: 長﨑 義徳 | D29: 施設管理チーム | F29: =IF(H29="",I29,H29) -> 070-3601-5755 | H29: 070-3601-5755 | I29: 090-4621-6574
B30: 3150022 | C30: 関 英夫 | D30: 施設管理チーム | F30: =IF(H30="",I30,H30) -> 070-3609-3812 | H30: 070-3609-3812 | I30: 090-4716-9267
B31: 3150024 | C31: 市川 孝 | D31: 施設管理チーム | F31: =IF(H31="",I31,H31) -> 070-3533-7393 | H31: 070-3533-7393 | I31: 090-7675-7609
B32: 3160011 | C32: 佐藤 友岐夫 | D32: 施設管理チーム | F32: =IF(H32="",I32,H32) -> 080-3566-8955 | H32: 080-3566-8955 | I32: 090-3241-8619
B33: 3170018 | C33: 石田 恵一 | D33: 施設管理チーム | F33: =IF(H33="",I33,H33) -> 090-6723-5666 | H33: 090-6723-5666 | I33: 090-1117-5188
B34: 3170005 | C34: 川崎 哲也 | D34: 施設管理チーム | F34: =IF(H34="",I34,H34) -> 090-3157-1610 | I34: 090-3157-1610 | J34: 時給
B35: 3170019 | C35: 作宮 和夫 | D35: 施設管理チーム | F35: =IF(H35="",I35,H35) -> 090-8490-0670 | I35: 090-8490-0670 | J35: 時給
B36: 3111001 | C36: 宮﨑 正行 | D36: テクニカルチーム | F36: =IF(H36="",I36,H36) -> 080-3451-6474 | H36: 080-3451-6474 | I36: 090-2205-3664
B37: 3109002 | C37: 加藤 純一 | D37: テクニカルチーム | F37: =IF(H37="",I37,H37) -> 080-3566-8974 | H37: 080-3566-8974 | I37: 090-9005-4611
B38: 3111006 | C38: 清水 豊 | D38: テクニカルチーム | F38: =IF(H38="",I38,H38) -> 080-4373-7695 | H38: 080-4373-7695 | I38: 090-2637-1434
B39: 3120010 | C39: 中山 透 | D39: テクニカルチーム | F39: =IF(H39="",I39,H39) -> 080-4581-1553 | H39: 080-4581-1553 | I39: 080-3159-1007
B40: 3120014 | C40: 瀧上 和樹 | D40: テクニカルチーム | F40: =IF(H40="",I40,H40) -> 080-4373-7793 | H40: 080-4373-7793 | I40: 080-4669-1341
...

Sheet Sheet1
A1: 社用携帯貸与者一覧 | F1: iphoneでのauID 電話番号
F2: iphoneでのauIDパス mmi0332938686
F3: ネットワーク暗証番号：8686
A4: 項番 | B4: 役職 | C4: 機種名 | D4: 対象回線番号 | E4: 貸与先 | F4: メールアドレス | G4: 前の使用者 | H4: 納品年月日 | I4: AppleID | J4: Pass | K4: 備考
A5: 1 | B5: 社員 | C5: iPhone5C_16GWH | D5: 08041420878 | E5: 新沼篤 | F5: niinuma-mmi@ezweb.ne.jp | H5: 2014.08.25 | I5: niinuma@mmin-net.co.jp | J5: Mmi0332938686
A6: 2 | B6: 社員 | C6: iPhone5C_16GWH | D6: 08035668957 | E6: 瀧田賢吾 | F6: takida-mmi@ezweb.ne.jp | H6: 2014.08.25
A7: 3 | B7: 社員 | C7: iPhoneSE-16S | D7: 08031737962 | E7: 桑田拓也 | F7: kuwata-mmi@ezweb.ne.jp | H7: 2016.10.28 | I7: kuwata@mmin-net.co.jp | J7: Mmi0332938686
A8: 4 | B8: 社員 | C8: iPhone5C_16GWH | D8: 08032706875 | E8: 伊藤恵 | F8: mito-mmi@ezweb.ne.jp | H8: 2014.08.25 | I8: mito@mmin-net.co.jp | J8: Mmi0332938686
A9: 5 | B9: 社員 | C9: iPhone5C_16GWH | D9: 08043737684 | E9: 斯波聡 | F9: shiba-mmi@ezweb.ne.jp | H9: 2014.08.25 | I9: shiba@mmin-net.co.jp | J9: Mmi0332938686
A10: 6 | B10: 社員 | C10: iPhone5C_16GWH | D10: 08036063448 | E10: 岸優里 | F10: kishi-mmi@ezweb.ne.jp | G10: 山浦雅美 | H10: 2014.08.25 | I10: kishi@mmin-net.co.jp | J10: Mmi0332938686
A11: 7 | B11: 社員 | C11: iPhone5C_16GWH | D11: 09098086751 | E11: 佐々木恵美 | F11: esasaki-mmi@ezweb.ne.jp | H11: 2014.08.25 | I11: sasaki@mmin-net.co.jp | J11: Mmi0332938686
A12: 8 | B12: 社員 | C12: iPhone5C_16GWH | D12: 08034467228 | E12: 東郷一哉 | F12: togo-mmi@ezweb.ne.jp | H12: 2014.08.28 | I12: togo@mmin-net.co.jp | J12: Mmi0332938686
A13: 9 | B13: 社員 | C13: iPhone5C_16GWH | D13: 08035668975 | E13: 田中宏樹 | F13: tanaka-mmi@ezweb.ne.jp | H13: 2014.08.28 | I13: tanaka@mmin-net.co.jp | J13: Mmi0332938686
A14: 10 | B14: 社員 | C14: iPhone5C_16GWH | D14: 08035668951 | E14: 白井正美 | F14: shirai-mmi@ezweb.ne.jp | H14: 2014.08.28 | I14: shirai@mmin-net.co.jp | J14: Mmi0332938686
A15: 11 | B15: 社員 | C15: iPhone6s | D15: 08035668958 | E15: 伏見晃一 | F15: fushimi-mmi@ezweb.ne.jp | H15: 2014.08.28 | I15: mmi.fushimi@icloud.com | J15: Mmi0332938686
A16: 12 | B16: 社員 | C16: iPhone5C_16GWH | D16: 08035668953 | E16: 青木博之 | F16: aoki-mmi@ezweb.ne.jp | H16: 2014.08.28 | I16: mmi_0002＠me.com | J16: Mmi0332938686
A17: 13 | B17: 社員 | C17: iPhone6_16GSL | D17: 08035668976 | E17: 飯嶋陽子 | F17: e-jima-mmi@ezweb.ne.jp | H17: 2014.08.28 | I17: iijima@mmin-net.co.jp | J17: Mmi0332938686
A18: 14 | B18: 社員 | C18: iPhone5C_16GWH | D18: 08035668956 | E18: 浅野博 | F18: asano-mmi@ezweb.ne.jp | H18: 2014.08.28 | I18: asano@mmin-net.co.jp | J18: Mmi0332938686
A19: 15 | B19: 社員 | C19: iPhone5C_16GWH | D19: 08035668955 | E19: 佐藤友岐夫 | F19: y.sato-mmi@ezweb.ne.jp | G19: 石田恵一 | H19: 2014.08.28 | I19: y-sato@mmin-net.co.jp | J19: Mmi0332938686
A20: 16 | B20: 社員 | C20: iPhone5C_16GWH | D20: 08035668978 | E20: 伊藤祐介 | F20: ito-mmi@ezweb.ne.jp | H20: 2014.08.28 | I20: ito@mmin-net.co.jp | J20: Mmi0332938686
A21: 17 | B21: 社員 | C21: iPhone5C_16GWH | D21: 09060337021 | E21: 白鳥大介 | F21: shiratori-mmi@ezweb.ne.jp | H21: 2014.08.28 | I21: shiratori@mmin-net.co.jp | J21: Mmi0332938686
A22: 18 | B22: 社員 | C22: iPhone5C_16GWH | D22: 08034516474 | E22: 宮﨑正行 | F22: miyazaki-mmi@ezweb.ne.jp | H22: 2014.08.28 | I22: miyzaki@mmin-net.co.jp | J22: Mmi0332938686
A23: 19 | B23: 社員 | C23: iPhone5C_16GWH | D23: 08043737694 | E23: 大澤邦明 | F23: osawa-mmi@ezweb.ne.jp | H23: 2014.08.28
A24: 20 | B24: 社員 | C24: iPhone5C_16GWH | D24: 08043737695 | E24: 清水豊 | F24: shimizu-mmi@ezweb.ne.jp | H24: 2014.08.28 | I24: shimizu@mmin-net.co.jp | J24: Mmi0332938686
A25: 21 | B25: 社員 | C25: iPhone5C_16GWH | D25: 08041068296 | E25: 下田隆弘 | F25: shimoda-mmi@ezweb.ne.jp | H25: 2014.08.28 | I25: shimoda@mmin-net.co.jp | J25: Mmi0332938686
A26: 22 | B26: 社員 | C26: iPhone6 | D26: 08045811553 | E26: 中山透 | F26: nakayama-mmi@ezweb.ne.jp | H26: 2015.10.23 | I26: nakayama@mmin-net.co.jp | J26: Mmi0332938686
A27: 23 | B27: 社員 | C27: iPhone5C_16GWH | D27: 08043737793 | E27: 瀧上和樹 | F27: takigami-mmi@ezweb.ne.jp | H27: 2014.08.28 | I27: takigami@mmin-net.co.jp | J27: Mmi0332938686
A28: 24 | B28: 社員 | C28: iPhone5C_16GWH | D28: 09098314911 | E28: 景山光司 | F28: kageyama-mmi@ezweb.ne.jp | H28: 2014.08.28 | I28: kageyama@mmin-net.co.jp | J28: Mmi0332938686
A29: 25 | B29: 社員 | C29: iPhone5C_16GWH | D29: 09090252358 | E29: 橋本修一 | F29: mmi_0001＠me.com | H29: 2014.08.28 | I29: mmi_0001＠me.com | J29: Mmi0332938686
A30: 26 | B30: 社員 | C30: iPhone5C_16GWH | D30: 09017915298 | E30: 松田豪之扶 | F30: matsuda-mmi@ezweb.ne.jp | H30: 2014.08.28 | J30: Mmi0332938686
A31: 27 | B31: 社員 | C31: iPhone5C_16GWH | D31: 08048623745 | E31: 福岡法和 | F31: fukuoka-mmi@ezweb.ne.jp | H31: 2014.08.28
A32: 28 | B32: 社員 | C32: iPhone5C_16GWH | D32: 08037543568 | E32: 日浦健二 | F32: hiura-mmi@ezweb.ne.jp | H32: 2017.1.19
A33: 29 | B33: 社員 | C33: iPhone6s | D33: 08079336122 | E33: 水澤浩二郎 | F33: mizusawa@ezweb.ne.jp | H33: 2014.08.28 | I33: mizusawa@mmin-net.co.jp | J33: Mmi0332938686
A34: 30 | B34: 社員 | C34: iPhone6s | D34: 08049056111 | E34: 羽場康雄 | F34: haba-mmi@ezweb.ne.jp | H34: 2014.08.28 | I34: mmi_0002＠me.com | J34: Mmi0332938686
A35: 31 | B35: 社員 | C35: iPhone5C_16GWH | D35: 08035668966 | E35: 明石健太 | F35: ｋakashi-mmi@ezweb.ne.jp | H35: 2014.08.28 | I35: akashi@mmin-net.co.jp | J35: Mmi0332938686
A36: 32 | B36: 社員 | C36: iPhone5C_16GWH | D36: 08034316721 | E36: 飯嶋由佳李 | F36: iijima-mmi@ezweb.ne.jp | H36: 2014.08.28 | I36: yiijima@mmin-net.co.jp | J36: Mmi0332938686
A37: 33 | B37: 社員 | C37: iPhone6s | D37: 08045811554 | E37: 松本泰貴 | F37: matsumoto-mmi@ezweb.ne.jp | H37: 2015.10.07 | I37: hmatsumoto@mmin-net.co.jp | J37: Mmi0332938686
A38: 34 | B38: 社員 | C38: iPhone5S_16GSL | D38: 08098024442 | F38: matsubayashi-mmi@ezweb.ne.jp | G38: 松林延幸 | H38: 2014.11.17 | I38: matsubayashi@mmin-net.co.jp | J38: Mmi0332938686 | K38: 本社保管中
A39: 35 | B39: 社員 | C39: iPhone5S_16GSL | D39: 08098024443 | E39: 工藤純子 | F39: kudo-mmi@ezweb.ne.jp | H39: 2014.11.17 | I39: kudo@mmin-net.co.jp | J39: Mmi0332938686
A40: 36 | B40: 社員 | C40: iPhone5S_16GGL | D40: 08098700199 | E40: 下地浩子 | F40: hshimoji-mmi@ezweb.ne.jp | H40: 2015.04.15 | I40: shimoji@mmi-net.co.jp | J40: Mmi0332938686
...

Sheet （参考）連絡網201704 
H1: hiura@mmin-net.co.jp
H3: 日浦 健二 | L3: 福岡 法和 | O3: 松田 豪之扶 | R3: 出口 栄一 | U3: 野田 哲男
H4: =IF(H3="","",VLOOKUP(H3,表示電話番号一覧!$C:$F,4,FALSE)) -> 080-3754-3568 | L4: =IF(L3="","",VLOOKUP(L3,表示電話番号一覧!$C:$F,4,FALSE)) -> 080-4862-3745 | O4: =IF(O3="","",VLOOKUP(O3,表示電話番号一覧!$C:$F,4,FALSE)) -> 090-1791-5298 | R4: =IF(R3="","",VLOOKUP(R3,表示電話番号一覧!$C:$F,4,FALSE)) -> 090-3104-3067 | U4: =IF(U3="","",VLOOKUP(U3,表示電話番号一覧!$C:$F,4,FALSE)) -> 080-3384-9464 | X4: =IF(X3="","",VLOOKUP(X3,表示電話番号一覧!$C:$F,4,FALSE)) | AA4: =IF(AA3="","",VLOOKUP(AA3,表示電話番号一覧!$C:$F,4,FALSE))
L6: 三浦 学 | O6: 川上 悟 | R6: 水澤 浩二郎 | U6: 松岡 幸恵 | X6: 山本 喬子 | AA6: 高橋 寿美
L7: =IF(L6="","",VLOOKUP(L6,表示電話番号一覧!$C:$F,4,FALSE)) -> 070-3514-2223 | O7: =IF(O6="","",VLOOKUP(O6,表示電話番号一覧!$C:$F,4,FALSE)) -> 070-3541-0264 | R7: =IF(R6="","",VLOOKUP(R6,表示電話番号一覧!$C:$F,4,FALSE)) -> 080-7933-6122 | U7: =IF(U6="","",VLOOKUP(U6,表示電話番号一覧!$C:$F,4,FALSE)) -> 090-2442-2655 | X7: =IF(X6="","",VLOOKUP(X6,表示電話番号一覧!$C:$F,4,FALSE)) -> #N/A | AA7: =IF(AA6="","",VLOOKUP(AA6,表示電話番号一覧!$C:$F,4,FALSE)) -> #N/A
L9: 松本 泰貴 | O9: 飯嶋 由佳李 | R9: 高石 薫 | U9: 安部 亮 | X9: 安藤 美穂 | AA9: 下地 浩子
L10: =IF(L9="","",VLOOKUP(L9,表示電話番号一覧!$C:$F,4,FALSE)) -> 080-4581-1554 | O10: =IF(O9="","",VLOOKUP(O9,表示電話番号一覧!$C:$F,4,FALSE)) -> 080-3431-6721 | R10: =IF(R9="","",VLOOKUP(R9,表示電話番号一覧!$C:$F,4,FALSE)) -> 080-3566-8973 | U10: =IF(U9="","",VLOOKUP(U9,表示電話番号一覧!$C:$F,4,FALSE)) -> 070-3854-6729 | X10: =IF(X9="","",VLOOKUP(X9,表示電話番号一覧!$C:$F,4,FALSE)) -> 070-3533-7394 | AA10: =IF(AA9="","",VLOOKUP(AA9,表示電話番号一覧!$C:$F,4,FALSE)) -> 080-9870-0199
L12: 伊藤 恵 | O12: 佐々木 恵美 | R12: 工藤 純子 | U12: 岸 優里
L13: =IF(L12="","",VLOOKUP(L12,表示電話番号一覧!$C:$F,4,FALSE)) -> 080-3270-6875 | O13: =IF(O12="","",VLOOKUP(O12,表示電話番号一覧!$C:$F,4,FALSE)) -> 090-9808-6751 | R13: =IF(R12="","",VLOOKUP(R12,表示電話番号一覧!$C:$F,4,FALSE)) -> 080-9802-4443 | U13: =IF(U12="","",VLOOKUP(U12,表示電話番号一覧!$C:$F,4,FALSE)) -> 080-3606-3448 | X13: =IF(X12="","",VLOOKUP(X12,表示電話番号一覧!$C:$F,4,FALSE)) | AA13: =IF(AA12="","",VLOOKUP(AA12,表示電話番号一覧!$C:$F,4,FALSE))
O15: 斯波 聡 | R15: 野口 直樹 | U15: 日吉 健一郎
B16: mmi_0001@me.com | H16: shirai-mmi@ezweb.ne.jp | L16: =IF(L15="","",VLOOKUP(L15,表示電話番号一覧!$C:$F,4,FALSE)) | O16: =IF(O15="","",VLOOKUP(O15,表示電話番号一覧!$C:$F,4,FALSE)) -> 080-4373-7684 | R16: =IF(R15="","",VLOOKUP(R15,表示電話番号一覧!$C:$F,4,FALSE)) -> 070-3854-6728 | U16: =IF(U15="","",VLOOKUP(U15,表示電話番号一覧!$C:$F,4,FALSE)) -> 070-3854-6730 | X16: =IF(X15="","",VLOOKUP(X15,表示電話番号一覧!$C:$F,4,FALSE)) | AA16: =IF(AA15="","",VLOOKUP(AA15,表示電話番号一覧!$C:$F,4,FALSE))
B18: 橋本 修一 | H18: 白井 正美 | L18: 宮﨑 正行 | O18: 清水 豊 | R18: 明石 健太 | U18: 齊藤 翔 | X18: 鑪（たたら）康介
B19: =IF(B18="","",VLOOKUP(B18,表示電話番号一覧!$C:$F,4,FALSE)) -> 090-9025-2358 | H19: =IF(H18="","",VLOOKUP(H18,表示電話番号一覧!$C:$F,4,FALSE)) -> 080-3566-8951 | L19: =IF(L18="","",VLOOKUP(L18,表示電話番号一覧!$C:$F,4,FALSE)) -> 080-3451-6474 | O19: =IF(O18="","",VLOOKUP(O18,表示電話番号一覧!$C:$F,4,FALSE)) -> 080-4373-7695 | R19: =IF(R18="","",VLOOKUP(R18,表示電話番号一覧!$C:$F,4,FALSE)) -> 080-3566-8966 | U19: =IF(U18="","",VLOOKUP(U18,表示電話番号一覧!$C:$F,4,FALSE)) -> 070-3629-7215 | X19: =IF(X18="","",VLOOKUP(X18,表示電話番号一覧!$C:$F,4,FALSE)) -> #N/A | AA19: =IF(AA18="","",VLOOKUP(AA18,表示電話番号一覧!$C:$F,4,FALSE))
O21: 中山 透 | R21: 加藤 純一 | U21: 瀧上 和樹 | X21: 鈴木 武史 | AA21: 松本 大輔
O22: =IF(O21="","",VLOOKUP(O21,表示電話番号一覧!$C:$F,4,FALSE)) -> 080-4581-1553 | R22: =IF(R21="","",VLOOKUP(R21,表示電話番号一覧!$C:$F,4,FALSE)) -> 080-3566-8974 | U22: =IF(U21="","",VLOOKUP(U21,表示電話番号一覧!$C:$F,4,FALSE)) -> 080-4373-7793 | X22: =IF(X21="","",VLOOKUP(X21,表示電話番号一覧!$C:$F,4,FALSE)) -> 070-3541-0263 | AA22: =IF(AA21="","",VLOOKUP(AA21,表示電話番号一覧!$C:$F,4,FALSE)) -> 070-3843-4639
O24: 鈴木 圭 | R24: 伊藤 祐介 | U24: 渡邊 良子 | X24: 大木 望愛
O25: =IF(O24="","",VLOOKUP(O24,表示電話番号一覧!$C:$F,4,FALSE)) -> 070-2165-7714 | R25: =IF(R24="","",VLOOKUP(R24,表示電話番号一覧!$C:$F,4,FALSE)) -> 080-3566-8978 | U25: =IF(U24="","",VLOOKUP(U24,表示電話番号一覧!$C:$F,4,FALSE)) -> 070-4201-6852 | X25: =IF(X24="","",VLOOKUP(X24,表示電話番号一覧!$C:$F,4,FALSE)) -> 090-2402-7362 | AA25: =IF(AA24="","",VLOOKUP(AA24,表示電話番号一覧!$C:$F,4,FALSE))
L27: 白鳥 大介 | O27: 田中 宏樹 | R27: 下田 隆弘 | U27: 伏見 晃一 | X27: 大澤 邦明
L28: =IF(L27="","",VLOOKUP(L27,表示電話番号一覧!$C:$F,4,FALSE)) -> 090-6033-7021 | O28: =IF(O27="","",VLOOKUP(O27,表示電話番号一覧!$C:$F,4,FALSE)) -> 080-3566-8975 | R28: =IF(R27="","",VLOOKUP(R27,表示電話番号一覧!$C:$F,4,FALSE)) -> 080-4106-8296 | U28: =IF(U27="","",VLOOKUP(U27,表示電話番号一覧!$C:$F,4,FALSE)) -> 080-3566-8958 | X28: =IF(X27="","",VLOOKUP(X27,表示電話番号一覧!$C:$F,4,FALSE)) -> 080-4373-8694 | AA28: =IF(AA27="","",VLOOKUP(AA27,表示電話番号一覧!$C:$F,4,FALSE))
O30: 東郷 一哉 | R30: 長﨑 義徳 | U30: 関 英夫 | X30: 佐藤 友岐夫
O31: =IF(O30="","",VLOOKUP(O30,表示電話番号一覧!$C:$F,4,FALSE)) -> 080-3446-7228 | R31: =IF(R30="","",VLOOKUP(R30,表示電話番号一覧!$C:$F,4,FALSE)) -> 070-3601-5755 | U31: =IF(U30="","",VLOOKUP(U30,表示電話番号一覧!$C:$F,4,FALSE)) -> 070-3609-3812 | X31: =IF(X30="","",VLOOKUP(X30,表示電話番号一覧!$C:$F,4,FALSE)) -> 080-3566-8955 | AA31: =IF(AA30="","",VLOOKUP(AA30,表示電話番号一覧!$C:$F,4,FALSE))
R33: 瀧田 賢吾 | U33: 小嶋 大樹 | X33: 市川 孝
R34: =IF(R33="","",VLOOKUP(R33,表示電話番号一覧!$C:$F,4,FALSE)) -> 080-3566-8957 | U34: =IF(U33="","",VLOOKUP(U33,表示電話番号一覧!$C:$F,4,FALSE)) -> #N/A | X34: =IF(X33="","",VLOOKUP(X33,表示電話番号一覧!$C:$F,4,FALSE)) -> 070-3533-7393 | AA34: =IF(AA33="","",VLOOKUP(AA33,表示電話番号一覧!$C:$F,4,FALSE))
L36: 磯 孝宏 | O36: 森 美弥 | R36: 川井 麻子 | U36: 矢吹 智代
H37: haba-mmi@ezweb.ne.jp | L37: =IF(L36="","",VLOOKUP(L36,表示電話番号一覧!$C:$F,4,FALSE)) -> 080-9819-8256 | O37: =IF(O36="","",VLOOKUP(O36,表示電話番号一覧!$C:$F,4,FALSE)) -> 080-4584-2248 | R37: =IF(R36="","",VLOOKUP(R36,表示電話番号一覧!$C:$F,4,FALSE)) -> #N/A | U37: =IF(U36="","",VLOOKUP(U36,表示電話番号一覧!$C:$F,4,FALSE)) -> 090-1047-0938 | X37: =IF(X36="","",VLOOKUP(X36,表示電話番号一覧!$C:$F,4,FALSE)) | AA37: =IF(AA36="","",VLOOKUP(AA36,表示電話番号一覧!$C:$F,4,FALSE))
H39: 羽場 康雄 | L39: 曽我 尚子 | O39: 新間 豊 | R39: 高橋 和夫 | U39: 梅津 香織 | X39: 難波 佳那子 | AA39: 岡田 仁美
H40: =IF(H39="","",VLOOKUP(H39,表示電話番号一覧!$C:$F,4,FALSE)) -> 080-4905-6111 | L40: =IF(L39="","",VLOOKUP(L39,表示電話番号一覧!$C:$F,4,FALSE)) -> 090-4241-0567 | O40: =IF(O39="","",VLOOKUP(O39,表示電話番号一覧!$C:$F,4,FALSE)) -> 090-4855-2641 | R40: =IF(R39="","",VLOOKUP(R39,表示電話番号一覧!$C:$F,4,FALSE)) -> 090-4938-1866 | U40: =IF(U39="","",VLOOKUP(U39,表示電話番号一覧!$C:$F,4,FALSE)) -> 090-9855-5534 | X40: =IF(X39="","",VLOOKUP(X39,表示電話番号一覧!$C:$F,4,FALSE)) -> #N/A | AA40: =IF(AA39="","",VLOOKUP(AA39,表示電話番号一覧!$C:$F,4,FALSE)) -> 080-2333-4494
L42: 青木 博之 | O42: 檜垣 壮 | R42: 松本 千絵 | U42: 桑田 拓也
E43: 社長不在の場合は | L43: =IF(L42="","",VLOOKUP(L42,表示電話番号一覧!$C:$F,4,FALSE)) -> 090-3238-0679 | O43: =IF(O42="","",VLOOKUP(O42,表示電話番号一覧!$C:$F,4,FALSE)) -> #N/A | R43: =IF(R42="","",VLOOKUP(R42,表示電話番号一覧!$C:$F,4,FALSE)) -> 080-2053-5731 | U43: =IF(U42="","",VLOOKUP(U42,表示電話番号一覧!$C:$F,4,FALSE)) -> 090-1213-2144 | X43: =IF(X42="","",VLOOKUP(X42,表示電話番号一覧!$C:$F,4,FALSE)) | AA43: =IF(AA42="","",VLOOKUP(AA42,表示電話番号一覧!$C:$F,4,FALSE))
E44: 経営管理部長が
E45: 代行して連絡をする | L45: 浅野 博 | O45: 金 英珉 | R45: 飯塚 武彦 | U45: 松山 大輔 | X45: ソン ソンショク | AA45: ユン ミヨン
L46: =IF(L45="","",VLOOKUP(L45,表示電話番号一覧!$C:$F,4,FALSE)) -> 080-3566-8956 | O46: =IF(O45="","",VLOOKUP(O45,表示電話番号一覧!$C:$F,4,FALSE)) -> 070-3547-4367 | R46: =IF(R45="","",VLOOKUP(R45,表示電話番号一覧!$C:$F,4,FALSE)) -> 070-3852-1867 | U46: =IF(U45="","",VLOOKUP(U45,表示電話番号一覧!$C:$F,4,FALSE)) -> 070-3864-2675 | X46: =IF(X45="","",VLOOKUP(X45,表示電話番号一覧!$C:$F,4,FALSE)) -> #N/A | AA46: =IF(AA45="","",VLOOKUP(AA45,表示電話番号一覧!$C:$F,4,FALSE)) -> #N/A
B47: マルハン危機情報センター
B48: ０３－５２２０－４９８４ | J48: ※ 震災等の安否確認では、連絡がとりにくい状況が予測されるため、キントーンのアプリ
J49: 『社員情報マスタ』の安否確認欄に 本人の怪我の有無、家族・家屋の状況』を記入してください
J50: キントーンに入力できない場合は、部門長にメールで報告してください

Sheet （参考）連絡網201710
G3: 日浦 健二 | K3: 福岡 法和 | N3: 松田 豪之扶 | Q3: 出口 栄一 | T3: 野田 哲男 | W3: 森 美弥
G4: =IF(G3="","",VLOOKUP(G3,表示電話番号一覧!$C:$F,4,FALSE)) -> 080-3754-3568 | K4: =IF(K3="","",VLOOKUP(K3,表示電話番号一覧!$C:$F,4,FALSE)) -> 080-4862-3745 | N4: =IF(N3="","",VLOOKUP(N3,表示電話番号一覧!$C:$F,4,FALSE)) -> 090-1791-5298 | Q4: =IF(Q3="","",VLOOKUP(Q3,表示電話番号一覧!$C:$F,4,FALSE)) -> 090-3104-3067 | T4: =IF(T3="","",VLOOKUP(T3,表示電話番号一覧!$C:$F,4,FALSE)) -> 080-3384-9464 | W4: =IF(W3="","",VLOOKUP(W3,表示電話番号一覧!$C:$F,4,FALSE)) -> 080-4584-2248 | Z4: =IF(Z3="","",VLOOKUP(Z3,表示電話番号一覧!$C:$F,4,FALSE))
G5: hiura@mmin-net.co.jp
K6: 三浦 学 | N6: 川上 悟 | Q6: 水澤 浩二郎 | T6: 松岡 幸恵 | W6: 高橋 寿美 | Z6: 小宮 慶宏 | AC6: 小宮 静佳
K7: =IF(K6="","",VLOOKUP(K6,表示電話番号一覧!$C:$F,4,FALSE)) -> 070-3514-2223 | N7: =IF(N6="","",VLOOKUP(N6,表示電話番号一覧!$C:$F,4,FALSE)) -> 070-3541-0264 | Q7: =IF(Q6="","",VLOOKUP(Q6,表示電話番号一覧!$C:$F,4,FALSE)) -> 080-7933-6122 | T7: 090-2442-2655 | W7: =IF(W6="","",VLOOKUP(W6,表示電話番号一覧!$C:$F,4,FALSE)) -> #N/A | Z7: 070-3831-8111 | AC7: 080-5746-0499
K9: 松本 泰貴 | N9: 飯嶋 由佳李 | Q9: 高石 薫 | T9: 安部 亮 | W9: 下地 浩子
K10: =IF(K9="","",VLOOKUP(K9,表示電話番号一覧!$C:$F,4,FALSE)) -> 080-4581-1554 | N10: =IF(N9="","",VLOOKUP(N9,表示電話番号一覧!$C:$F,4,FALSE)) -> 080-3431-6721 | Q10: =IF(Q9="","",VLOOKUP(Q9,表示電話番号一覧!$C:$F,4,FALSE)) -> 080-3566-8973 | T10: =IF(T9="","",VLOOKUP(T9,表示電話番号一覧!$C:$F,4,FALSE)) -> 070-3854-6729 | W10: =IF(W9="","",VLOOKUP(W9,表示電話番号一覧!$C:$F,4,FALSE)) -> 080-9870-0199
B12: 社長不在の場合は | K12: 伊藤 恵 | N12: 佐々木 恵美 | Q12: 工藤 純子 | T12: 岸 優里
B13: 経営管理部長が | K13: =IF(K12="","",VLOOKUP(K12,表示電話番号一覧!$C:$F,4,FALSE)) -> 080-3270-6875 | N13: =IF(N12="","",VLOOKUP(N12,表示電話番号一覧!$C:$F,4,FALSE)) -> 090-9808-6751 | Q13: =IF(Q12="","",VLOOKUP(Q12,表示電話番号一覧!$C:$F,4,FALSE)) -> 080-9802-4443 | T13: =IF(T12="","",VLOOKUP(T12,表示電話番号一覧!$C:$F,4,FALSE)) -> 080-3606-3448 | W13: =IF(W12="","",VLOOKUP(W12,表示電話番号一覧!$C:$F,4,FALSE)) | Z13: =IF(Z12="","",VLOOKUP(Z12,表示電話番号一覧!$C:$F,4,FALSE))
B14: 代行して連絡をする
N15: 斯波 聡 | Q15: 野口 直樹 | T15: 日吉 健一郎 | W15: 松山 大輔 | Z15: 重白 一久
K16: =IF(K15="","",VLOOKUP(K15,表示電話番号一覧!$C:$F,4,FALSE)) | N16: =IF(N15="","",VLOOKUP(N15,表示電話番号一覧!$C:$F,4,FALSE)) -> 080-4373-7684 | Q16: =IF(Q15="","",VLOOKUP(Q15,表示電話番号一覧!$C:$F,4,FALSE)) -> 070-3854-6728 | T16: =IF(T15="","",VLOOKUP(T15,表示電話番号一覧!$C:$F,4,FALSE)) -> 070-3854-6730 | W16: =IF(W15="","",VLOOKUP(W15,表示電話番号一覧!$C:$F,4,FALSE)) -> 070-3864-2675 | Z16: =IF(Z15="","",VLOOKUP(Z15,表示電話番号一覧!$C:$F,4,FALSE)) -> #N/A
B18: 橋本 修一 | G18: 白井 正美 | K18: 宮﨑 正行 | N18: 清水 豊 | Q18: 明石 健太 | T18: 齊藤 翔 | W18: 鑪（たたら）康介
B19: =IF(B18="","",VLOOKUP(B18,表示電話番号一覧!$C:$F,4,FALSE)) -> 090-9025-2358 | G19: =IF(G18="","",VLOOKUP(G18,表示電話番号一覧!$C:$F,4,FALSE)) -> 080-3566-8951 | K19: =IF(K18="","",VLOOKUP(K18,表示電話番号一覧!$C:$F,4,FALSE)) -> 080-3451-6474 | N19: =IF(N18="","",VLOOKUP(N18,表示電話番号一覧!$C:$F,4,FALSE)) -> 080-4373-7695 | Q19: =IF(Q18="","",VLOOKUP(Q18,表示電話番号一覧!$C:$F,4,FALSE)) -> 080-3566-8966 | T19: =IF(T18="","",VLOOKUP(T18,表示電話番号一覧!$C:$F,4,FALSE)) -> 070-3629-7215 | W19: =IF(W18="","",VLOOKUP(W18,表示電話番号一覧!$C:$F,4,FALSE)) -> #N/A | Z19: =IF(Z18="","",VLOOKUP(Z18,表示電話番号一覧!$C:$F,4,FALSE))
B20: mmi_0001@me.com | G20: shirai-mmi@ezweb.ne.jp
N21: 中山 透 | Q21: 加藤 純一 | T21: 瀧上 和樹 | W21: 鈴木 武史 | Z21: 松本 大輔
N22: =IF(N21="","",VLOOKUP(N21,表示電話番号一覧!$C:$F,4,FALSE)) -> 080-4581-1553 | Q22: =IF(Q21="","",VLOOKUP(Q21,表示電話番号一覧!$C:$F,4,FALSE)) -> 080-3566-8974 | T22: =IF(T21="","",VLOOKUP(T21,表示電話番号一覧!$C:$F,4,FALSE)) -> 080-4373-7793 | W22: =IF(W21="","",VLOOKUP(W21,表示電話番号一覧!$C:$F,4,FALSE)) -> 070-3541-0263 | Z22: =IF(Z21="","",VLOOKUP(Z21,表示電話番号一覧!$C:$F,4,FALSE)) -> 070-3843-4639
N24: 鈴木 圭 | Q24: 伊藤 祐介 | T24: 渡邊 良子 | W24: 大木 望愛 | Z24: 二村 眞弓
N25: =IF(N24="","",VLOOKUP(N24,表示電話番号一覧!$C:$F,4,FALSE)) -> 070-2165-7714 | Q25: =IF(Q24="","",VLOOKUP(Q24,表示電話番号一覧!$C:$F,4,FALSE)) -> 080-3566-8978 | T25: =IF(T24="","",VLOOKUP(T24,表示電話番号一覧!$C:$F,4,FALSE)) -> 070-4201-6852 | W25: =IF(W24="","",VLOOKUP(W24,表示電話番号一覧!$C:$F,4,FALSE)) -> 090-2402-7362 | Z25: =IF(Z24="","",VLOOKUP(Z24,表示電話番号一覧!$C:$F,4,FALSE)) -> 090-6950-1788
K27: 白鳥 大介 | N27: 田中 宏樹 | Q27: 下田 隆弘 | T27: 大澤 邦明
K28: =IF(K27="","",VLOOKUP(K27,表示電話番号一覧!$C:$F,4,FALSE)) -> 090-6033-7021 | N28: =IF(N27="","",VLOOKUP(N27,表示電話番号一覧!$C:$F,4,FALSE)) -> 080-3566-8975 | Q28: =IF(Q27="","",VLOOKUP(Q27,表示電話番号一覧!$C:$F,4,FALSE)) -> 080-4106-8296 | T28: =IF(T27="","",VLOOKUP(T27,表示電話番号一覧!$C:$F,4,FALSE)) -> 080-4373-8694 | Z28: =IF(Z27="","",VLOOKUP(Z27,表示電話番号一覧!$C:$F,4,FALSE))
N30: 東郷 一哉 | Q30: 長﨑 義徳 | T30: 関 英夫 | W30: 佐藤 友岐夫 | Z30: 伏見 晃一
N31: =IF(N30="","",VLOOKUP(N30,表示電話番号一覧!$C:$F,4,FALSE)) -> 080-3446-7228 | Q31: =IF(Q30="","",VLOOKUP(Q30,表示電話番号一覧!$C:$F,4,FALSE)) -> 070-3601-5755 | T31: =IF(T30="","",VLOOKUP(T30,表示電話番号一覧!$C:$F,4,FALSE)) -> 070-3609-3812 | W31: =IF(W30="","",VLOOKUP(W30,表示電話番号一覧!$C:$F,4,FALSE)) -> 080-3566-8955 | Z31: =IF(Z30="","",VLOOKUP(Z30,表示電話番号一覧!$C:$F,4,FALSE)) -> 080-3566-8958
Q33: 瀧田 賢吾 | T33: 市川 孝 | W33: 川崎 哲也
Q34: =IF(Q33="","",VLOOKUP(Q33,表示電話番号一覧!$C:$F,4,FALSE)) -> 080-3566-8957 | T34: =IF(T33="","",VLOOKUP(T33,表示電話番号一覧!$C:$F,4,FALSE)) -> 070-3533-7393 | W34: 070-4504-5778
K36: 磯 孝宏 | N36: 浅川 喜希 | Q36: 矢吹 智代
K37: =IF(K36="","",VLOOKUP(K36,表示電話番号一覧!$C:$F,4,FALSE)) -> 080-9819-8256 | N37: =IF(N36="","",VLOOKUP(N36,表示電話番号一覧!$C:$F,4,FALSE)) -> 080-5190-8426 | Q37: =IF(Q36="","",VLOOKUP(Q36,表示電話番号一覧!$C:$F,4,FALSE)) -> 090-1047-0938 | W37: =IF(W36="","",VLOOKUP(W36,表示電話番号一覧!$C:$F,4,FALSE)) | Z37: =IF(Z36="","",VLOOKUP(Z36,表示電話番号一覧!$C:$F,4,FALSE))
G39: 羽場 康雄 | K39: 曽我 尚子 | N39: 新間 豊 | Q39: 高橋 和夫 | T39: 梅津 香織 | W39: 難波 佳那子 | Z39: 岡田 仁美
G40: =IF(G39="","",VLOOKUP(G39,表示電話番号一覧!$C:$F,4,FALSE)) -> 080-4905-6111 | K40: =IF(K39="","",VLOOKUP(K39,表示電話番号一覧!$C:$F,4,FALSE)) -> 090-4241-0567 | N40: =IF(N39="","",VLOOKUP(N39,表示電話番号一覧!$C:$F,4,FALSE)) -> 090-4855-2641 | Q40: =IF(Q39="","",VLOOKUP(Q39,表示電話番号一覧!$C:$F,4,FALSE)) -> 090-4938-1866 | T40: =IF(T39="","",VLOOKUP(T39,表示電話番号一覧!$C:$F,4,FALSE)) -> 090-9855-5534 | W40: =IF(W39="","",VLOOKUP(W39,表示電話番号一覧!$C:$F,4,FALSE)) -> #N/A | Z40: =IF(Z39="","",VLOOKUP(Z39,表示電話番号一覧!$C:$F,4,FALSE)) -> 080-2333-4494
G41: haba-mmi@ezweb.ne.jp
K42: 青木 博之 | N42: 檜垣 壮 | Q42: 松本 千絵 | T42: 桑田 拓也
K43: 090-3238-0679 | N43: =IF(N42="","",VLOOKUP(N42,表示電話番号一覧!$C:$F,4,FALSE)) -> #N/A | Q43: =IF(Q42="","",VLOOKUP(Q42,表示電話番号一覧!$C:$F,4,FALSE)) -> 080-2053-5731 | T43: 090-1213-2144 | W43: =IF(W42="","",VLOOKUP(W42,表示電話番号一覧!$C:$F,4,FALSE))
K45: 浅野 博 | N45: 金 英珉 | Q45: 飯塚 武彦 | T45: 安藤 美穂
K46: =IF(K45="","",VLOOKUP(K45,表示電話番号一覧!$C:$F,4,FALSE)) -> 080-3566-8956 | N46: =IF(N45="","",VLOOKUP(N45,表示電話番号一覧!$C:$F,4,FALSE)) -> 070-3547-4367 | Q46: =IF(Q45="","",VLOOKUP(Q45,表示電話番号一覧!$C:$F,4,FALSE)) -> 070-3852-1867 | T46: =IF(T45="","",VLOOKUP(T45,表示電話番号一覧!$C:$F,4,FALSE)) -> 070-3533-7394
N48: ソン ソンショク | Q48: ユン ミヨン | T48: 金 恩志 | W48: 朴 秀彬 | Z48: ヴォン ティ リエウ
N49: =IF(N48="","",VLOOKUP(N48,表示電話番号一覧!$C:$F,4,FALSE)) -> #N/A | Q49: =IF(Q48="","",VLOOKUP(Q48,表示電話番号一覧!$C:$F,4,FALSE)) -> #N/A | T49: 070-3862-8149 | W49: 080-3566-8953 | Z49: 070-3872-7701
B51: マルハン危機情報センター | I51: ※ 震災等の安否確認では、連絡がとりにくい状況が予測されるため、キントーンのアプリ
B52: ０３－５２２０－４９８４ | I52: 『社員情報マスタ』の安否確認欄に 本人の怪我の有無、家族・家屋の状況』を記入してください
I53: キントーンに入力できない場合は、部門長にメールで報告してください
